<robot name = "robot">
    <link name="20">
        <inertial>
            <origin xyz="0 0 0.5" rpy="0 0 0"/>
            <mass value="1" />
            <inertia ixx="100" ixy="0" ixz="0" iyy="100" iyz="0" izz="100" />
        </inertial>
        <visual>
            <origin xyz="0 0 0.5" rpy="0 0 0"/>
            <geometry>
                <box size="0.4 0.4 0.4" />
            </geometry>
            <material name="Blue">
            <color rgba = "0 0 1 1"/>
            </material>
        </visual>
        <collision>
            <origin xyz="0 0 0.5" rpy="0 0 0"/>
            <geometry>
                <box size="0.4 0.4 0.4" />
            </geometry>
        </collision>
    </link>
    <joint name="20_1" type="revolute">
       <parent link="20"/>
       <child  link="21"/>
       <origin rpy="0 0 0" xyz="0.2 0 0.5" />
       <axis xyz="0 0 1"/>
       <limit effort="0.0" lower="-3.14159" upper="3.14159" velocity="0.0"/>
    </joint>
    <link name="21">
        <inertial>
            <origin xyz="0.1893615331886373 0 0" rpy="0 0 0"/>
            <mass value="1" />
            <inertia ixx="100" ixy="0" ixz="0" iyy="100" iyz="0" izz="100" />
        </inertial>
        <visual>
            <origin xyz="0.1893615331886373 0 0" rpy="0 0 0"/>
            <geometry>
                <box size="0.3787230663772746 0.3259388166284166 0.43397055126954964" />
            </geometry>
            <material name="Green">
            <color rgba = "0 1 0 1"/>
            </material>
        </visual>
        <collision>
            <origin xyz="0.1893615331886373 0 0" rpy="0 0 0"/>
            <geometry>
                <box size="0.3787230663772746 0.3259388166284166 0.43397055126954964" />
            </geometry>
        </collision>
    </link>
    <joint name="21_2" type="revolute">
       <parent link="21"/>
       <child  link="22"/>
       <origin rpy="0 0 0" xyz="-0.2 0 0.0" />
       <axis xyz="0 0 1"/>
       <limit effort="0.0" lower="-3.14159" upper="3.14159" velocity="0.0"/>
    </joint>
    <link name="22">
        <inertial>
            <origin xyz="-0.10758494886195188 0 0" rpy="0 0 0"/>
            <mass value="1" />
            <inertia ixx="100" ixy="0" ixz="0" iyy="100" iyz="0" izz="100" />
        </inertial>
        <visual>
            <origin xyz="-0.10758494886195188 0 0" rpy="0 0 0"/>
            <geometry>
                <box size="0.21516989772390377 0.23443013209635144 0.38318329010725527" />
            </geometry>
            <material name="Green">
            <color rgba = "0 1 0 1"/>
            </material>
        </visual>
        <collision>
            <origin xyz="-0.10758494886195188 0 0" rpy="0 0 0"/>
            <geometry>
                <box size="0.21516989772390377 0.23443013209635144 0.38318329010725527" />
            </geometry>
        </collision>
    </link>
    <joint name="22_3" type="revolute">
       <parent link="22"/>
       <child  link="23"/>
       <origin rpy="0 0 0" xyz="0.29694648205058916 0 0.0" />
       <axis xyz="0 0 1"/>
       <limit effort="0.0" lower="-3.14159" upper="3.14159" velocity="0.0"/>
    </joint>
    <link name="23">
        <inertial>
            <origin xyz="0.10678160015010336 0 0" rpy="0 0 0"/>
            <mass value="1" />
            <inertia ixx="100" ixy="0" ixz="0" iyy="100" iyz="0" izz="100" />
        </inertial>
        <visual>
            <origin xyz="0.10678160015010336 0 0" rpy="0 0 0"/>
            <geometry>
                <box size="0.21356320030020673 0.2620564478149429 0.3208207468041609" />
            </geometry>
            <material name="Green">
            <color rgba = "0 1 0 1"/>
            </material>
        </visual>
        <collision>
            <origin xyz="0.10678160015010336 0 0" rpy="0 0 0"/>
            <geometry>
                <box size="0.21356320030020673 0.2620564478149429 0.3208207468041609" />
            </geometry>
        </collision>
    </link>
    <joint name="23_4" type="revolute">
       <parent link="23"/>
       <child  link="24"/>
       <origin rpy="0 0 0" xyz="-0.2143665490120552 0 0.0" />
       <axis xyz="1 0 0"/>
       <limit effort="0.0" lower="-3.14159" upper="3.14159" velocity="0.0"/>
    </joint>
    <link name="24">
        <inertial>
            <origin xyz="-0.19541678113436603 0 0" rpy="0 0 0"/>
            <mass value="1" />
            <inertia ixx="100" ixy="0" ixz="0" iyy="100" iyz="0" izz="100" />
        </inertial>
        <visual>
            <origin xyz="-0.19541678113436603 0 0" rpy="0 0 0"/>
            <geometry>
                <box size="0.39083356226873206 0.2581654779668308 0.347621560125832" />
            </geometry>
            <material name="Blue">
            <color rgba = "0 0 1 1"/>
            </material>
        </visual>
        <collision>
            <origin xyz="-0.19541678113436603 0 0" rpy="0 0 0"/>
            <geometry>
                <box size="0.39083356226873206 0.2581654779668308 0.347621560125832" />
            </geometry>
        </collision>
    </link>
    <joint name="24_5" type="revolute">
       <parent link="24"/>
       <child  link="25"/>
       <origin rpy="0 0 0" xyz="0.3021983812844694 0 0.0" />
       <axis xyz="1 0 0"/>
       <limit effort="0.0" lower="-3.14159" upper="3.14159" velocity="0.0"/>
    </joint>
    <link name="25">
        <inertial>
            <origin xyz="0.17747720251456744 0 0" rpy="0 0 0"/>
            <mass value="1" />
            <inertia ixx="100" ixy="0" ixz="0" iyy="100" iyz="0" izz="100" />
        </inertial>
        <visual>
            <origin xyz="0.17747720251456744 0 0" rpy="0 0 0"/>
            <geometry>
                <box size="0.3549544050291349 0.2544677975312166 0.28237235088442897" />
            </geometry>
            <material name="Blue">
            <color rgba = "0 0 1 1"/>
            </material>
        </visual>
        <collision>
            <origin xyz="0.17747720251456744 0 0" rpy="0 0 0"/>
            <geometry>
                <box size="0.3549544050291349 0.2544677975312166 0.28237235088442897" />
            </geometry>
        </collision>
    </link>
    <joint name="25_6" type="revolute">
       <parent link="25"/>
       <child  link="26"/>
       <origin rpy="0 0 0" xyz="-0.3728939836489335 0 0.0" />
       <axis xyz="0 1 0"/>
       <limit effort="0.0" lower="-3.14159" upper="3.14159" velocity="0.0"/>
    </joint>
    <link name="26">
        <inertial>
            <origin xyz="-0.14191737519405226 0 0" rpy="0 0 0"/>
            <mass value="1" />
            <inertia ixx="100" ixy="0" ixz="0" iyy="100" iyz="0" izz="100" />
        </inertial>
        <visual>
            <origin xyz="-0.14191737519405226 0 0" rpy="0 0 0"/>
            <geometry>
                <box size="0.2838347503881045 0.2978347518609224 0.3005386362455208" />
            </geometry>
            <material name="Blue">
            <color rgba = "0 0 1 1"/>
            </material>
        </visual>
        <collision>
            <origin xyz="-0.14191737519405226 0 0" rpy="0 0 0"/>
            <geometry>
                <box size="0.2838347503881045 0.2978347518609224 0.3005386362455208" />
            </geometry>
        </collision>
    </link>
    <joint name="26_7" type="revolute">
       <parent link="26"/>
       <child  link="27"/>
       <origin rpy="0 0 0" xyz="0.3193945777086197 0 0.0" />
       <axis xyz="0 0 1"/>
       <limit effort="0.0" lower="-3.14159" upper="3.14159" velocity="0.0"/>
    </joint>
    <link name="27">
        <inertial>
            <origin xyz="0.11768082990915646 0 0" rpy="0 0 0"/>
            <mass value="1" />
            <inertia ixx="100" ixy="0" ixz="0" iyy="100" iyz="0" izz="100" />
        </inertial>
        <visual>
            <origin xyz="0.11768082990915646 0 0" rpy="0 0 0"/>
            <geometry>
                <box size="0.23536165981831292 0.2719855768107062 0.31644160164351" />
            </geometry>
            <material name="Green">
            <color rgba = "0 1 0 1"/>
            </material>
        </visual>
        <collision>
            <origin xyz="0.11768082990915646 0 0" rpy="0 0 0"/>
            <geometry>
                <box size="0.23536165981831292 0.2719855768107062 0.31644160164351" />
            </geometry>
        </collision>
    </link>
    <joint name="27_8" type="revolute">
       <parent link="27"/>
       <child  link="28"/>
       <origin rpy="0 0 0" xyz="-0.2595982051032087 0 0.0" />
       <axis xyz="0 0 1"/>
       <limit effort="0.0" lower="-3.14159" upper="3.14159" velocity="0.0"/>
    </joint>
    <link name="28">
        <inertial>
            <origin xyz="-0.10463294786852836 0 0" rpy="0 0 0"/>
            <mass value="1" />
            <inertia ixx="100" ixy="0" ixz="0" iyy="100" iyz="0" izz="100" />
        </inertial>
        <visual>
            <origin xyz="-0.10463294786852836 0 0" rpy="0 0 0"/>
            <geometry>
                <box size="0.20926589573705673 0.23773379828912944 0.20393527678240833" />
            </geometry>
            <material name="Green">
            <color rgba = "0 1 0 1"/>
            </material>
        </visual>
        <collision>
            <origin xyz="-0.10463294786852836 0 0" rpy="0 0 0"/>
            <geometry>
                <box size="0.20926589573705673 0.23773379828912944 0.20393527678240833" />
            </geometry>
        </collision>
    </link>
    <joint name="28_9" type="revolute">
       <parent link="28"/>
       <child  link="29"/>
       <origin rpy="0 0 0" xyz="0.22231377777768482 0 0.0" />
       <axis xyz="1 0 0"/>
       <limit effort="0.0" lower="-3.14159" upper="3.14159" velocity="0.0"/>
    </joint>
    <link name="29">
        <inertial>
            <origin xyz="0.1599078170561833 0 0" rpy="0 0 0"/>
            <mass value="1" />
            <inertia ixx="100" ixy="0" ixz="0" iyy="100" iyz="0" izz="100" />
        </inertial>
        <visual>
            <origin xyz="0.1599078170561833 0 0" rpy="0 0 0"/>
            <geometry>
                <box size="0.3198156341123666 0.2462185980979092 0.3004562313781319" />
            </geometry>
            <material name="Green">
            <color rgba = "0 1 0 1"/>
            </material>
        </visual>
        <collision>
            <origin xyz="0.1599078170561833 0 0" rpy="0 0 0"/>
            <geometry>
                <box size="0.3198156341123666 0.2462185980979092 0.3004562313781319" />
            </geometry>
        </collision>
    </link>
    <joint name="29_10" type="revolute">
       <parent link="29"/>
       <child  link="210"/>
       <origin rpy="0 0 0" xyz="-0.2645407649247116 0 0.0" />
       <axis xyz="1 0 0"/>
       <limit effort="0.0" lower="-3.14159" upper="3.14159" velocity="0.0"/>
    </joint>
    <link name="210">
        <inertial>
            <origin xyz="-0.142548272191284 0 0" rpy="0 0 0"/>
            <mass value="1" />
            <inertia ixx="100" ixy="0" ixz="0" iyy="100" iyz="0" izz="100" />
        </inertial>
        <visual>
            <origin xyz="-0.142548272191284 0 0" rpy="0 0 0"/>
            <geometry>
                <box size="0.285096544382568 0.29355444914824824 0.33541262004533934" />
            </geometry>
            <material name="Blue">
            <color rgba = "0 0 1 1"/>
            </material>
        </visual>
        <collision>
            <origin xyz="-0.142548272191284 0 0" rpy="0 0 0"/>
            <geometry>
                <box size="0.285096544382568 0.29355444914824824 0.33541262004533934" />
            </geometry>
        </collision>
    </link>
    <joint name="210_11" type="revolute">
       <parent link="210"/>
       <child  link="211"/>
       <origin rpy="0 0 0" xyz="0.30245608924746725 0 0.0" />
       <axis xyz="0 1 0"/>
       <limit effort="0.0" lower="-3.14159" upper="3.14159" velocity="0.0"/>
    </joint>
    <link name="211">
        <inertial>
            <origin xyz="0.1072980796347744 0 0" rpy="0 0 0"/>
            <mass value="1" />
            <inertia ixx="100" ixy="0" ixz="0" iyy="100" iyz="0" izz="100" />
        </inertial>
        <visual>
            <origin xyz="0.1072980796347744 0 0" rpy="0 0 0"/>
            <geometry>
                <box size="0.2145961592695488 0.2445254255480413 0.3810649604105" />
            </geometry>
            <material name="Green">
            <color rgba = "0 1 0 1"/>
            </material>
        </visual>
        <collision>
            <origin xyz="0.1072980796347744 0 0" rpy="0 0 0"/>
            <geometry>
                <box size="0.2145961592695488 0.2445254255480413 0.3810649604105" />
            </geometry>
        </collision>
    </link>
</robot>