<robot name = "robot">
    <link name="0">
        <inertial>
            <origin xyz="0 0 1.5" rpy="0 0 0"/>
            <mass value="1" />
            <inertia ixx="100" ixy="0" ixz="0" iyy="100" iyz="0" izz="100" />
        </inertial>
        <visual>
            <origin xyz="0 0 1.5" rpy="0 0 0"/>
            <geometry>
                <box size="0.4 0.4 0.4" />
            </geometry>
            <material name="Green">
            <color rgba = "0 1 0 1"/>
            </material>
        </visual>
        <collision>
            <origin xyz="0 0 1.5" rpy="0 0 0"/>
            <geometry>
                <box size="0.4 0.4 0.4" />
            </geometry>
        </collision>
    </link>
    <joint name="0_1" type="revolute">
       <parent link="0"/>
       <child  link="1"/>
       <origin rpy="0 0 0" xyz="0.2 0 1.5" />
       <axis xyz="0 0 1"/>
       <limit effort="0.0" lower="-3.14159" upper="3.14159" velocity="0.0"/>
    </joint>
    <link name="1">
        <inertial>
            <origin xyz="0.13167461135867406 0 0" rpy="0 0 0"/>
            <mass value="1" />
            <inertia ixx="100" ixy="0" ixz="0" iyy="100" iyz="0" izz="100" />
        </inertial>
        <visual>
            <origin xyz="0.13167461135867406 0 0" rpy="0 0 0"/>
            <geometry>
                <box size="0.2633492227173481 0.4495358384762623 0.23878905257549693" />
            </geometry>
            <material name="Green">
            <color rgba = "0 1 0 1"/>
            </material>
        </visual>
        <collision>
            <origin xyz="0.13167461135867406 0 0" rpy="0 0 0"/>
            <geometry>
                <box size="0.2633492227173481 0.4495358384762623 0.23878905257549693" />
            </geometry>
        </collision>
    </link>
    <joint name="1_2" type="revolute">
       <parent link="1"/>
       <child  link="2"/>
       <origin rpy="0 0 0" xyz="-0.06832538864132595 0 0.11939452628774846" />
       <axis xyz="0 0 1"/>
       <limit effort="0.0" lower="-3.14159" upper="3.14159" velocity="0.0"/>
    </joint>
    <link name="2">
        <inertial>
            <origin xyz="0 0 0.200536706857463" rpy="0 0 0"/>
            <mass value="1" />
            <inertia ixx="100" ixy="0" ixz="0" iyy="100" iyz="0" izz="100" />
        </inertial>
        <visual>
            <origin xyz="0 0 0.200536706857463" rpy="0 0 0"/>
            <geometry>
                <box size="0.2980282457403902 0.46051025189331063 0.401073413714926" />
            </geometry>
            <material name="Blue">
            <color rgba = "0 0 1 1"/>
            </material>
        </visual>
        <collision>
            <origin xyz="0 0 0.200536706857463" rpy="0 0 0"/>
            <geometry>
                <box size="0.2980282457403902 0.46051025189331063 0.401073413714926" />
            </geometry>
        </collision>
    </link>
    <joint name="2_3" type="revolute">
       <parent link="2"/>
       <child  link="3"/>
       <origin rpy="0 0 0" xyz="0.0 0 0.28167888742717756" />
       <axis xyz="0 1 0"/>
       <limit effort="0.0" lower="-3.14159" upper="3.14159" velocity="0.0"/>
    </joint>
    <link name="3">
        <inertial>
            <origin xyz="0 0 0.20768814882464723" rpy="0 0 0"/>
            <mass value="1" />
            <inertia ixx="100" ixy="0" ixz="0" iyy="100" iyz="0" izz="100" />
        </inertial>
        <visual>
            <origin xyz="0 0 0.20768814882464723" rpy="0 0 0"/>
            <geometry>
                <box size="0.2572608435397243 0.49864026031070025 0.41537629764929446" />
            </geometry>
            <material name="Blue">
            <color rgba = "0 0 1 1"/>
            </material>
        </visual>
        <collision>
            <origin xyz="0 0 0.20768814882464723" rpy="0 0 0"/>
            <geometry>
                <box size="0.2572608435397243 0.49864026031070025 0.41537629764929446" />
            </geometry>
        </collision>
    </link>
    <joint name="3_4" type="revolute">
       <parent link="3"/>
       <child  link="4"/>
       <origin rpy="0 0 0" xyz="0.0 0 0.21483959079183132" />
       <axis xyz="0 1 0"/>
       <limit effort="0.0" lower="-3.14159" upper="3.14159" velocity="0.0"/>
    </joint>
    <link name="4">
        <inertial>
            <origin xyz="0 0 0.29990637050347646" rpy="0 0 0"/>
            <mass value="1" />
            <inertia ixx="100" ixy="0" ixz="0" iyy="100" iyz="0" izz="100" />
        </inertial>
        <visual>
            <origin xyz="0 0 0.29990637050347646" rpy="0 0 0"/>
            <geometry>
                <box size="0.2655595814847772 0.4637013225971158 0.5998127410069529" />
            </geometry>
            <material name="Blue">
            <color rgba = "0 0 1 1"/>
            </material>
        </visual>
        <collision>
            <origin xyz="0 0 0.29990637050347646" rpy="0 0 0"/>
            <geometry>
                <box size="0.2655595814847772 0.4637013225971158 0.5998127410069529" />
            </geometry>
        </collision>
    </link>
    <joint name="4_5" type="revolute">
       <parent link="4"/>
       <child  link="5"/>
       <origin rpy="0 0 0" xyz="0.0 0.2318506612985579 0.09221822167882898" />
       <axis xyz="0 1 0"/>
       <limit effort="0.0" lower="-3.14159" upper="3.14159" velocity="0.0"/>
    </joint>
    <link name="5">
        <inertial>
            <origin xyz="0 0.23346163232094194 0" rpy="0 0 0"/>
            <mass value="1" />
            <inertia ixx="100" ixy="0" ixz="0" iyy="100" iyz="0" izz="100" />
        </inertial>
        <visual>
            <origin xyz="0 0.23346163232094194 0" rpy="0 0 0"/>
            <geometry>
                <box size="0.2772934343930529 0.4669232646418839 0.4428924317533706" />
            </geometry>
            <material name="Green">
            <color rgba = "0 1 0 1"/>
            </material>
        </visual>
        <collision>
            <origin xyz="0 0.23346163232094194 0" rpy="0 0 0"/>
            <geometry>
                <box size="0.2772934343930529 0.4669232646418839 0.4428924317533706" />
            </geometry>
        </collision>
    </link>
    <joint name="5_6" type="revolute">
       <parent link="5"/>
       <child  link="6"/>
       <origin rpy="0 0 0" xyz="0.0 0.235072603343326 0.0" />
       <axis xyz="0 0 1"/>
       <limit effort="0.0" lower="-3.14159" upper="3.14159" velocity="0.0"/>
    </joint>
    <link name="6">
        <inertial>
            <origin xyz="0 0.24911078148445961 0" rpy="0 0 0"/>
            <mass value="1" />
            <inertia ixx="100" ixy="0" ixz="0" iyy="100" iyz="0" izz="100" />
        </inertial>
        <visual>
            <origin xyz="0 0.24911078148445961 0" rpy="0 0 0"/>
            <geometry>
                <box size="0.2511116330837603 0.49822156296891923 0.4793006867495579" />
            </geometry>
            <material name="Green">
            <color rgba = "0 1 0 1"/>
            </material>
        </visual>
        <collision>
            <origin xyz="0 0.24911078148445961 0" rpy="0 0 0"/>
            <geometry>
                <box size="0.2511116330837603 0.49822156296891923 0.4793006867495579" />
            </geometry>
        </collision>
    </link>
    <joint name="6_7" type="revolute">
       <parent link="6"/>
       <child  link="7"/>
       <origin rpy="0 0 0" xyz="0.0 0.015649149163517673 -0.23965034337477895" />
       <axis xyz="0 1 0"/>
       <limit effort="0.0" lower="-3.14159" upper="3.14159" velocity="0.0"/>
    </joint>
    <link name="7">
        <inertial>
            <origin xyz="0 0 -0.30366665908836504" rpy="0 0 0"/>
            <mass value="1" />
            <inertia ixx="100" ixy="0" ixz="0" iyy="100" iyz="0" izz="100" />
        </inertial>
        <visual>
            <origin xyz="0 0 -0.30366665908836504" rpy="0 0 0"/>
            <geometry>
                <box size="0.23416885437001936 0.47488185992444754 0.6073333181767301" />
            </geometry>
            <material name="Green">
            <color rgba = "0 1 0 1"/>
            </material>
        </visual>
        <collision>
            <origin xyz="0 0 -0.30366665908836504" rpy="0 0 0"/>
            <geometry>
                <box size="0.23416885437001936 0.47488185992444754 0.6073333181767301" />
            </geometry>
        </collision>
    </link>
    <joint name="7_8" type="revolute">
       <parent link="7"/>
       <child  link="8"/>
       <origin rpy="0 0 0" xyz="0.11708442718500968 0.0 -0.06401631571358601" />
       <axis xyz="1 0 0"/>
       <limit effort="0.0" lower="-3.14159" upper="3.14159" velocity="0.0"/>
    </joint>
    <link name="8">
        <inertial>
            <origin xyz="0.12599747338294065 0 0" rpy="0 0 0"/>
            <mass value="1" />
            <inertia ixx="100" ixy="0" ixz="0" iyy="100" iyz="0" izz="100" />
        </inertial>
        <visual>
            <origin xyz="0.12599747338294065 0 0" rpy="0 0 0"/>
            <geometry>
                <box size="0.2519949467658813 0.4352126670864672 0.4057623273762856" />
            </geometry>
            <material name="Green">
            <color rgba = "0 1 0 1"/>
            </material>
        </visual>
        <collision>
            <origin xyz="0.12599747338294065 0 0" rpy="0 0 0"/>
            <geometry>
                <box size="0.2519949467658813 0.4352126670864672 0.4057623273762856" />
            </geometry>
        </collision>
    </link>
    <joint name="8_9" type="revolute">
       <parent link="8"/>
       <child  link="9"/>
       <origin rpy="0 0 0" xyz="0.008913046197930985 0.2176063335432336 0.0" />
       <axis xyz="0 0 1"/>
       <limit effort="0.0" lower="-3.14159" upper="3.14159" velocity="0.0"/>
    </joint>
    <link name="9">
        <inertial>
            <origin xyz="0 0.2377972626825222 0" rpy="0 0 0"/>
            <mass value="1" />
            <inertia ixx="100" ixy="0" ixz="0" iyy="100" iyz="0" izz="100" />
        </inertial>
        <visual>
            <origin xyz="0 0.2377972626825222 0" rpy="0 0 0"/>
            <geometry>
                <box size="0.2225680393064355 0.4755945253650444 0.46182171403937844" />
            </geometry>
            <material name="Green">
            <color rgba = "0 1 0 1"/>
            </material>
        </visual>
        <collision>
            <origin xyz="0 0.2377972626825222 0" rpy="0 0 0"/>
            <geometry>
                <box size="0.2225680393064355 0.4755945253650444 0.46182171403937844" />
            </geometry>
        </collision>
    </link>
    <joint name="9_10" type="revolute">
       <parent link="9"/>
       <child  link="10"/>
       <origin rpy="0 0 0" xyz="0.0 0.02019092913928855 -0.23091085701968922" />
       <axis xyz="1 0 0"/>
       <limit effort="0.0" lower="-3.14159" upper="3.14159" velocity="0.0"/>
    </joint>
    <link name="10">
        <inertial>
            <origin xyz="0 0 -0.30112058663288965" rpy="0 0 0"/>
            <mass value="1" />
            <inertia ixx="100" ixy="0" ixz="0" iyy="100" iyz="0" izz="100" />
        </inertial>
        <visual>
            <origin xyz="0 0 -0.30112058663288965" rpy="0 0 0"/>
            <geometry>
                <box size="0.2239434155555456 0.42041500472774934 0.6022411732657793" />
            </geometry>
            <material name="Blue">
            <color rgba = "0 0 1 1"/>
            </material>
        </visual>
        <collision>
            <origin xyz="0 0 -0.30112058663288965" rpy="0 0 0"/>
            <geometry>
                <box size="0.2239434155555456 0.42041500472774934 0.6022411732657793" />
            </geometry>
        </collision>
    </link>
</robot>