<robot name = "robot">
    <link name="0">
        <inertial>
            <origin xyz="0 0 0.5" rpy="0 0 0"/>
            <mass value="1" />
            <inertia ixx="100" ixy="0" ixz="0" iyy="100" iyz="0" izz="100" />
        </inertial>
        <visual>
            <origin xyz="0 0 0.5" rpy="0 0 0"/>
            <geometry>
                <box size="0.4 0.4 0.4" />
            </geometry>
            <material name="Blue">
            <color rgba = "0 0 1 1"/>
            </material>
        </visual>
        <collision>
            <origin xyz="0 0 0.5" rpy="0 0 0"/>
            <geometry>
                <box size="0.4 0.4 0.4" />
            </geometry>
        </collision>
    </link>
    <joint name="0_1" type="revolute">
       <parent link="0"/>
       <child  link="1"/>
       <origin rpy="0 0 0" xyz="0.2 0 0.25" />
       <axis xyz="0 0 1"/>
       <limit effort="0.0" lower="-3.14159" upper="3.14159" velocity="0.0"/>
    </joint>
    <link name="1">
        <inertial>
            <origin xyz="0.23172487016170146 0 0" rpy="0 0 0"/>
            <mass value="1" />
            <inertia ixx="100" ixy="0" ixz="0" iyy="100" iyz="0" izz="100" />
        </inertial>
        <visual>
            <origin xyz="0.23172487016170146 0 0" rpy="0 0 0"/>
            <geometry>
                <box size="0.4634497403234029 0.38482667985487595 0.49462490144201277" />
            </geometry>
            <material name="Blue">
            <color rgba = "0 0 1 1"/>
            </material>
        </visual>
        <collision>
            <origin xyz="0.23172487016170146 0 0" rpy="0 0 0"/>
            <geometry>
                <box size="0.4634497403234029 0.38482667985487595 0.49462490144201277" />
            </geometry>
        </collision>
    </link>
    <joint name="1_2" type="revolute">
       <parent link="1"/>
       <child  link="2"/>
       <origin rpy="0 0 0" xyz="0 -0.38482667985487595 0" />
       <axis xyz="0 1 0"/>
       <limit effort="0.0" lower="-3.14159" upper="3.14159" velocity="0.0"/>
    </joint>
    <link name="2">
        <inertial>
            <origin xyz="0 -0.22384415264921992 0" rpy="0 0 0"/>
            <mass value="1" />
            <inertia ixx="100" ixy="0" ixz="0" iyy="100" iyz="0" izz="100" />
        </inertial>
        <visual>
            <origin xyz="0 -0.22384415264921992 0" rpy="0 0 0"/>
            <geometry>
                <box size="0.40755530531766526 0.44768830529843984 0.49712708106281234" />
            </geometry>
            <material name="Green">
            <color rgba = "0 1 0 1"/>
            </material>
        </visual>
        <collision>
            <origin xyz="0 -0.22384415264921992 0" rpy="0 0 0"/>
            <geometry>
                <box size="0.40755530531766526 0.44768830529843984 0.49712708106281234" />
            </geometry>
        </collision>
    </link>
    <joint name="2_3" type="revolute">
       <parent link="2"/>
       <child  link="3"/>
       <origin rpy="0 0 0" xyz="0.40755530531766526 0 0" />
       <axis xyz="0 1 0"/>
       <limit effort="0.0" lower="-3.14159" upper="3.14159" velocity="0.0"/>
    </joint>
    <link name="3">
        <inertial>
            <origin xyz="0.12430902499540511 0 0" rpy="0 0 0"/>
            <mass value="1" />
            <inertia ixx="100" ixy="0" ixz="0" iyy="100" iyz="0" izz="100" />
        </inertial>
        <visual>
            <origin xyz="0.12430902499540511 0 0" rpy="0 0 0"/>
            <geometry>
                <box size="0.24861804999081022 0.29091336116633615 0.3878040172221531" />
            </geometry>
            <material name="Green">
            <color rgba = "0 1 0 1"/>
            </material>
        </visual>
        <collision>
            <origin xyz="0.12430902499540511 0 0" rpy="0 0 0"/>
            <geometry>
                <box size="0.24861804999081022 0.29091336116633615 0.3878040172221531" />
            </geometry>
        </collision>
    </link>
    <joint name="3_4" type="revolute">
       <parent link="3"/>
       <child  link="4"/>
       <origin rpy="0 0 0" xyz="0 0 -0.3878040172221531" />
       <axis xyz="0 1 0"/>
       <limit effort="0.0" lower="-3.14159" upper="3.14159" velocity="0.0"/>
    </joint>
    <link name="4">
        <inertial>
            <origin xyz="0 0 -0.12682357489850593" rpy="0 0 0"/>
            <mass value="1" />
            <inertia ixx="100" ixy="0" ixz="0" iyy="100" iyz="0" izz="100" />
        </inertial>
        <visual>
            <origin xyz="0 0 -0.12682357489850593" rpy="0 0 0"/>
            <geometry>
                <box size="0.3929073217245461 0.3476509418914583 0.25364714979701186" />
            </geometry>
            <material name="Blue">
            <color rgba = "0 0 1 1"/>
            </material>
        </visual>
        <collision>
            <origin xyz="0 0 -0.12682357489850593" rpy="0 0 0"/>
            <geometry>
                <box size="0.3929073217245461 0.3476509418914583 0.25364714979701186" />
            </geometry>
        </collision>
    </link>
    <joint name="4_5" type="revolute">
       <parent link="4"/>
       <child  link="5"/>
       <origin rpy="0 0 0" xyz="0 -0.3476509418914583 0" />
       <axis xyz="0 1 0"/>
       <limit effort="0.0" lower="-3.14159" upper="3.14159" velocity="0.0"/>
    </joint>
    <link name="5">
        <inertial>
            <origin xyz="0 -0.23363540680633235 0" rpy="0 0 0"/>
            <mass value="1" />
            <inertia ixx="100" ixy="0" ixz="0" iyy="100" iyz="0" izz="100" />
        </inertial>
        <visual>
            <origin xyz="0 -0.23363540680633235 0" rpy="0 0 0"/>
            <geometry>
                <box size="0.26100136936729956 0.4672708136126647 0.3849480335775399" />
            </geometry>
            <material name="Blue">
            <color rgba = "0 0 1 1"/>
            </material>
        </visual>
        <collision>
            <origin xyz="0 -0.23363540680633235 0" rpy="0 0 0"/>
            <geometry>
                <box size="0.26100136936729956 0.4672708136126647 0.3849480335775399" />
            </geometry>
        </collision>
    </link>
    <joint name="5_6" type="revolute">
       <parent link="5"/>
       <child  link="6"/>
       <origin rpy="0 0 0" xyz="-0.26100136936729956 0 0" />
       <axis xyz="0 1 0"/>
       <limit effort="0.0" lower="-3.14159" upper="3.14159" velocity="0.0"/>
    </joint>
    <link name="6">
        <inertial>
            <origin xyz="-0.15119754803975377 0 0" rpy="0 0 0"/>
            <mass value="1" />
            <inertia ixx="100" ixy="0" ixz="0" iyy="100" iyz="0" izz="100" />
        </inertial>
        <visual>
            <origin xyz="-0.15119754803975377 0 0" rpy="0 0 0"/>
            <geometry>
                <box size="0.30239509607950754 0.4335901209472173 0.32674411440098056" />
            </geometry>
            <material name="Green">
            <color rgba = "0 1 0 1"/>
            </material>
        </visual>
        <collision>
            <origin xyz="-0.15119754803975377 0 0" rpy="0 0 0"/>
            <geometry>
                <box size="0.30239509607950754 0.4335901209472173 0.32674411440098056" />
            </geometry>
        </collision>
    </link>
    <joint name="6_7" type="revolute">
       <parent link="6"/>
       <child  link="7"/>
       <origin rpy="0 0 0" xyz="0 -0.4335901209472173 0" />
       <axis xyz="1 0 0"/>
       <limit effort="0.0" lower="-3.14159" upper="3.14159" velocity="0.0"/>
    </joint>
    <link name="7">
        <inertial>
            <origin xyz="0 -0.16545968416051848 0" rpy="0 0 0"/>
            <mass value="1" />
            <inertia ixx="100" ixy="0" ixz="0" iyy="100" iyz="0" izz="100" />
        </inertial>
        <visual>
            <origin xyz="0 -0.16545968416051848 0" rpy="0 0 0"/>
            <geometry>
                <box size="0.26461881988586494 0.33091936832103697 0.3296802944464657" />
            </geometry>
            <material name="Green">
            <color rgba = "0 1 0 1"/>
            </material>
        </visual>
        <collision>
            <origin xyz="0 -0.16545968416051848 0" rpy="0 0 0"/>
            <geometry>
                <box size="0.26461881988586494 0.33091936832103697 0.3296802944464657" />
            </geometry>
        </collision>
    </link>
</robot>