<robot name = "robot">
    <link name="0">
        <inertial>
            <origin xyz="0 0 1.5" rpy="0 0 0"/>
            <mass value="1" />
            <inertia ixx="100" ixy="0" ixz="0" iyy="100" iyz="0" izz="100" />
        </inertial>
        <visual>
            <origin xyz="0 0 1.5" rpy="0 0 0"/>
            <geometry>
                <box size="0.4 0.4 0.4" />
            </geometry>
            <material name="Blue">
            <color rgba = "0 0 1 1"/>
            </material>
        </visual>
        <collision>
            <origin xyz="0 0 1.5" rpy="0 0 0"/>
            <geometry>
                <box size="0.4 0.4 0.4" />
            </geometry>
        </collision>
    </link>
    <joint name="0_1" type="revolute">
       <parent link="0"/>
       <child  link="1"/>
       <origin rpy="0 0 0" xyz="0.2 0 1.5" />
       <axis xyz="0 0 1"/>
       <limit effort="0.0" lower="-3.14159" upper="3.14159" velocity="0.0"/>
    </joint>
    <link name="1">
        <inertial>
            <origin xyz="0.1927199180342564 0 0" rpy="0 0 0"/>
            <mass value="1" />
            <inertia ixx="100" ixy="0" ixz="0" iyy="100" iyz="0" izz="100" />
        </inertial>
        <visual>
            <origin xyz="0.1927199180342564 0 0" rpy="0 0 0"/>
            <geometry>
                <box size="0.3854398360685128 0.3486440392806881 0.3519142537088832" />
            </geometry>
            <material name="Blue">
            <color rgba = "0 0 1 1"/>
            </material>
        </visual>
        <collision>
            <origin xyz="0.1927199180342564 0 0" rpy="0 0 0"/>
            <geometry>
                <box size="0.3854398360685128 0.3486440392806881 0.3519142537088832" />
            </geometry>
        </collision>
    </link>
    <joint name="1_2" type="revolute">
       <parent link="1"/>
       <child  link="2"/>
       <origin rpy="0 0 0" xyz="-0.007280081965743618 0 0.1759571268544416" />
       <axis xyz="0 1 0"/>
       <limit effort="0.0" lower="-3.14159" upper="3.14159" velocity="0.0"/>
    </joint>
    <link name="2">
        <inertial>
            <origin xyz="0 0 0.29234775613089575" rpy="0 0 0"/>
            <mass value="1" />
            <inertia ixx="100" ixy="0" ixz="0" iyy="100" iyz="0" izz="100" />
        </inertial>
        <visual>
            <origin xyz="0 0 0.29234775613089575" rpy="0 0 0"/>
            <geometry>
                <box size="0.25736565630099384 0.4901029859428795 0.5846955122617915" />
            </geometry>
            <material name="Green">
            <color rgba = "0 1 0 1"/>
            </material>
        </visual>
        <collision>
            <origin xyz="0 0 0.29234775613089575" rpy="0 0 0"/>
            <geometry>
                <box size="0.25736565630099384 0.4901029859428795 0.5846955122617915" />
            </geometry>
        </collision>
    </link>
    <joint name="2_3" type="revolute">
       <parent link="2"/>
       <child  link="3"/>
       <origin rpy="0 0 0" xyz="0.12868282815049692 0 0.11639062927645427" />
       <axis xyz="0 1 0"/>
       <limit effort="0.0" lower="-3.14159" upper="3.14159" velocity="0.0"/>
    </joint>
    <link name="3">
        <inertial>
            <origin xyz="0.12369897502008556 0 0" rpy="0 0 0"/>
            <mass value="1" />
            <inertia ixx="100" ixy="0" ixz="0" iyy="100" iyz="0" izz="100" />
        </inertial>
        <visual>
            <origin xyz="0.12369897502008556 0 0" rpy="0 0 0"/>
            <geometry>
                <box size="0.24739795004017112 0.49342376578140024 0.654230085626131" />
            </geometry>
            <material name="Green">
            <color rgba = "0 1 0 1"/>
            </material>
        </visual>
        <collision>
            <origin xyz="0.12369897502008556 0 0" rpy="0 0 0"/>
            <geometry>
                <box size="0.24739795004017112 0.49342376578140024 0.654230085626131" />
            </geometry>
        </collision>
    </link>
    <joint name="3_4" type="revolute">
       <parent link="3"/>
       <child  link="4"/>
       <origin rpy="0 0 0" xyz="0.11871512188967423 0 0.0" />
       <axis xyz="0 1 0"/>
       <limit effort="0.0" lower="-3.14159" upper="3.14159" velocity="0.0"/>
    </joint>
    <link name="4">
        <inertial>
            <origin xyz="0.13718105055735255 0 0" rpy="0 0 0"/>
            <mass value="1" />
            <inertia ixx="100" ixy="0" ixz="0" iyy="100" iyz="0" izz="100" />
        </inertial>
        <visual>
            <origin xyz="0.13718105055735255 0 0" rpy="0 0 0"/>
            <geometry>
                <box size="0.2743621011147051 0.4427224995613169 0.44075183818327857" />
            </geometry>
            <material name="Green">
            <color rgba = "0 1 0 1"/>
            </material>
        </visual>
        <collision>
            <origin xyz="0.13718105055735255 0 0" rpy="0 0 0"/>
            <geometry>
                <box size="0.2743621011147051 0.4427224995613169 0.44075183818327857" />
            </geometry>
        </collision>
    </link>
    <joint name="4_5" type="revolute">
       <parent link="4"/>
       <child  link="5"/>
       <origin rpy="0 0 0" xyz="0.013482075537266991 -0.22136124978065844 0" />
       <axis xyz="0 0 1"/>
       <limit effort="0.0" lower="-3.14159" upper="3.14159" velocity="0.0"/>
    </joint>
    <link name="5">
        <inertial>
            <origin xyz="0 -0.24036258151106893 0" rpy="0 0 0"/>
            <mass value="1" />
            <inertia ixx="100" ixy="0" ixz="0" iyy="100" iyz="0" izz="100" />
        </inertial>
        <visual>
            <origin xyz="0 -0.24036258151106893 0" rpy="0 0 0"/>
            <geometry>
                <box size="0.2807215717557156 0.48072516302213786 0.6267848400560464" />
            </geometry>
            <material name="Blue">
            <color rgba = "0 0 1 1"/>
            </material>
        </visual>
        <collision>
            <origin xyz="0 -0.24036258151106893 0" rpy="0 0 0"/>
            <geometry>
                <box size="0.2807215717557156 0.48072516302213786 0.6267848400560464" />
            </geometry>
        </collision>
    </link>
    <joint name="5_6" type="revolute">
       <parent link="5"/>
       <child  link="6"/>
       <origin rpy="0 0 0" xyz="-0.1403607858778578 -0.019001331730410492 0.0" />
       <axis xyz="0 0 1"/>
       <limit effort="0.0" lower="-3.14159" upper="3.14159" velocity="0.0"/>
    </joint>
    <link name="6">
        <inertial>
            <origin xyz="-0.1097883043049914 0 0" rpy="0 0 0"/>
            <mass value="1" />
            <inertia ixx="100" ixy="0" ixz="0" iyy="100" iyz="0" izz="100" />
        </inertial>
        <visual>
            <origin xyz="-0.1097883043049914 0 0" rpy="0 0 0"/>
            <geometry>
                <box size="0.2195766086099828 0.45248558607217987 0.5915732558227198" />
            </geometry>
            <material name="Green">
            <color rgba = "0 1 0 1"/>
            </material>
        </visual>
        <collision>
            <origin xyz="-0.1097883043049914 0 0" rpy="0 0 0"/>
            <geometry>
                <box size="0.2195766086099828 0.45248558607217987 0.5915732558227198" />
            </geometry>
        </collision>
    </link>
    <joint name="6_7" type="revolute">
       <parent link="6"/>
       <child  link="7"/>
       <origin rpy="0 0 0" xyz="0.030572481572866406 0.22624279303608993 0.0" />
       <axis xyz="0 1 0"/>
       <limit effort="0.0" lower="-3.14159" upper="3.14159" velocity="0.0"/>
    </joint>
    <link name="7">
        <inertial>
            <origin xyz="0 0.20937282724410117 0" rpy="0 0 0"/>
            <mass value="1" />
            <inertia ixx="100" ixy="0" ixz="0" iyy="100" iyz="0" izz="100" />
        </inertial>
        <visual>
            <origin xyz="0 0.20937282724410117 0" rpy="0 0 0"/>
            <geometry>
                <box size="0.23955310253662485 0.41874565448820233 0.4494619940891822" />
            </geometry>
            <material name="Blue">
            <color rgba = "0 0 1 1"/>
            </material>
        </visual>
        <collision>
            <origin xyz="0 0.20937282724410117 0" rpy="0 0 0"/>
            <geometry>
                <box size="0.23955310253662485 0.41874565448820233 0.4494619940891822" />
            </geometry>
        </collision>
    </link>
    <joint name="7_8" type="revolute">
       <parent link="7"/>
       <child  link="8"/>
       <origin rpy="0 0 0" xyz="0.0 -0.016869965791988767 0.2247309970445911" />
       <axis xyz="1 0 0"/>
       <limit effort="0.0" lower="-3.14159" upper="3.14159" velocity="0.0"/>
    </joint>
    <link name="8">
        <inertial>
            <origin xyz="0 0 0.34844743074836315" rpy="0 0 0"/>
            <mass value="1" />
            <inertia ixx="100" ixy="0" ixz="0" iyy="100" iyz="0" izz="100" />
        </inertial>
        <visual>
            <origin xyz="0 0 0.34844743074836315" rpy="0 0 0"/>
            <geometry>
                <box size="0.2795004898635607 0.4823652027060712 0.6968948614967263" />
            </geometry>
            <material name="Blue">
            <color rgba = "0 0 1 1"/>
            </material>
        </visual>
        <collision>
            <origin xyz="0 0 0.34844743074836315" rpy="0 0 0"/>
            <geometry>
                <box size="0.2795004898635607 0.4823652027060712 0.6968948614967263" />
            </geometry>
        </collision>
    </link>
    <joint name="8_9" type="revolute">
       <parent link="8"/>
       <child  link="9"/>
       <origin rpy="0 0 0" xyz="0.0 0.2411826013530356 0.12371643370377194" />
       <axis xyz="1 0 0"/>
       <limit effort="0.0" lower="-3.14159" upper="3.14159" velocity="0.0"/>
    </joint>
    <link name="9">
        <inertial>
            <origin xyz="0 0.20251030816140878 0" rpy="0 0 0"/>
            <mass value="1" />
            <inertia ixx="100" ixy="0" ixz="0" iyy="100" iyz="0" izz="100" />
        </inertial>
        <visual>
            <origin xyz="0 0.20251030816140878 0" rpy="0 0 0"/>
            <geometry>
                <box size="0.2748060075300834 0.40502061632281755 0.41316268184032556" />
            </geometry>
            <material name="Blue">
            <color rgba = "0 0 1 1"/>
            </material>
        </visual>
        <collision>
            <origin xyz="0 0.20251030816140878 0" rpy="0 0 0"/>
            <geometry>
                <box size="0.2748060075300834 0.40502061632281755 0.41316268184032556" />
            </geometry>
        </collision>
    </link>
</robot>